File: packages/experimentalTreatingIsiPol/experimentaltreatingisipol-0.0.71.tar.gz/experimentaltreatingisipol-0.0.71/DataArquives/Specimen_RawData_1.csv
Deformação 1 comprimento do gabarito;"50,00000";mm
Deformação à tração (Deformação 1) comprimento do gabarito;"50,00000";mm
CargaemBreak (Standard);"433,15952";N
Deformação 1emBreak (Standard);"0,45206";mm/mm
Deformação à tração (Deformação 1)emBreak (Standard);"0,45859";mm/mm
DeslocamentoemBreak (Standard);"27,58437";mm
Deslocamento à traçãoemBreak (Standard);"22,92945";mm
Observação;""

Tempo;Travessa;Carga;Extensometro
(s);(mm);(N);(mm)
"0,00000";"0,00600";"3,46858";"0,32635"
"0,02000";"0,00850";"3,50164";"0,32681"
"0,04000";"0,01950";"4,40845";"0,32668"
"0,06000";"0,03887";"7,93212";"0,32610"
"0,08000";"0,06169";"14,75709";"0,32594"
"0,10000";"0,08369";"23,67317";"0,32588"
"0,12000";"0,10350";"32,74790";"0,32656"
"0,14000";"0,12137";"40,90481";"0,32635"
"0,16000";"0,13831";"47,87867";"0,32712"
"0,18000";"0,15519";"54,04363";"0,32689"
"0,20000";"0,17219";"59,91394";"0,32726"
"0,22000";"0,18925";"65,68376";"0,32774"
"0,24000";"0,20619";"71,38317";"0,32776"
"0,26000";"0,22319";"76,99057";"0,32736"
"0,28000";"0,24012";"82,51028";"0,32799"
"0,30000";"0,25700";"87,91978";"0,33262"
"0,32000";"0,27387";"93,23138";"0,33927"
"0,34000";"0,29081";"98,45402";"0,34661"
"0,36000";"0,30762";"103,57554";"0,35397"
"0,38000";"0,32431";"108,62672";"0,36132"
"0,40000";"0,34094";"113,52864";"0,36843"
"0,42000";"0,35762";"118,38660";"0,37466"
"0,44000";"0,37431";"123,17119";"0,37935"
"0,46000";"0,39094";"127,89404";"0,38340"
"0,48000";"0,40756";"132,57126";"0,38920"
"0,50000";"0,42425";"137,18828";"0,39460"
"0,52000";"0,44081";"141,72043";"0,40090"
"0,54000";"0,45737";"146,23030";"0,40760"
"0,56000";"0,47406";"150,68912";"0,41499"
"0,58000";"0,49081";"155,07916";"0,42262"
"0,60000";"0,50762";"159,50035";"0,43155"
"0,62000";"0,52444";"163,90137";"0,44014"
"0,64000";"0,54125";"168,24138";"0,44847"
"0,66000";"0,55794";"172,51498";"0,45487"
"0,68000";"0,57456";"176,73296";"0,46106"
"0,70000";"0,59112";"180,87598";"0,46630"
"0,72000";"0,60775";"184,90868";"0,47204"
"0,74000";"0,62437";"188,95889";"0,47914"
"0,76000";"0,64094";"192,98006";"0,48744"
"0,78000";"0,65756";"196,92384";"0,49585"
"0,80000";"0,67419";"200,80573";"0,50430"
"0,82000";"0,69087";"204,69473";"0,51461"
"0,84000";"0,70744";"208,52763";"0,52611"
"0,86000";"0,72412";"212,32234";"0,53691"
"0,88000";"0,74087";"216,11833";"0,54537"
"0,90000";"0,75756";"219,86044";"0,55179"
"0,92000";"0,77431";"223,57626";"0,55760"
"0,94000";"0,79112";"227,27750";"0,56601"
"0,96000";"0,80787";"230,91315";"0,57512"
"0,98000";"0,82450";"234,52455";"0,58165"
"1,00000";"0,84106";"238,10513";"0,59017"
"1,02000";"0,85769";"241,58078";"0,59913"
"1,04000";"0,87437";"245,02420";"0,60670"
"1,06000";"0,89094";"248,51303";"0,61382"
"1,08000";"0,90756";"251,91357";"0,62028"
"1,10000";"0,92425";"255,28685";"0,62702"
"1,12000";"0,94087";"258,65698";"0,63288"
"1,14000";"0,95737";"261,97083";"0,63892"
"1,16000";"0,97400";"265,20700";"0,64421"
"1,18000";"0,99075";"268,47128";"0,65163"
"1,20000";"1,00750";"271,72260";"0,66108"
"1,22000";"1,02419";"274,94479";"0,67219"
"1,24000";"1,04106";"278,14532";"0,68064"
"1,26000";"1,05787";"281,34866";"0,68810"
"1,28000";"1,07450";"284,51297";"0,69465"
"1,30000";"1,09112";"287,59979";"0,70045"
"1,32000";"1,10781";"290,66019";"0,70736"
"1,34000";"1,12444";"293,69562";"0,71555"
"1,36000";"1,14100";"296,69189";"0,72509"
"1,38000";"1,15756";"299,64819";"0,73286"
"1,40000";"1,17419";"302,59576";"0,73967"
"1,42000";"1,19081";"305,52060";"0,74788"
"1,44000";"1,20737";"308,41095";"0,75538"
"1,46000";"1,22406";"311,28088";"0,76380"
"1,48000";"1,24081";"314,13406";"0,77376"
"1,50000";"1,25750";"317,00266";"0,78357"
"1,52000";"1,27425";"319,85760";"0,79471"
"1,54000";"1,29106";"322,67984";"0,80472"
"1,56000";"1,30794";"325,49860";"0,81418"
"1,58000";"1,32456";"328,30692";"0,82111"
"1,60000";"1,34119";"331,03256";"0,82746"
"1,62000";"1,35787";"333,73111";"0,83311"
"1,64000";"1,37450";"336,39294";"0,83951"
"1,66000";"1,39100";"339,05475";"0,84790"
"1,68000";"1,40762";"341,67621";"0,85590"
"1,70000";"1,42425";"344,28705";"0,86343"
"1,72000";"1,44081";"346,86417";"0,87078"
"1,74000";"1,45744";"349,41599";"0,87716"
"1,76000";"1,47406";"351,94897";"0,88388"
"1,78000";"1,49081";"354,51016";"0,88909"
"1,80000";"1,50756";"357,07288";"0,89519"
"1,82000";"1,52431";"359,60660";"0,90220"
"1,84000";"1,54119";"362,12006";"0,90984"
"1,86000";"1,55794";"364,64191";"0,91771"
"1,88000";"1,57456";"367,11295";"0,92541"
"1,90000";"1,59119";"369,55200";"0,93495"
"1,92000";"1,60775";"371,93567";"0,94559"
"1,94000";"1,62437";"374,28134";"0,95670"
"1,96000";"1,64094";"376,63229";"0,96556"
"1,98000";"1,65756";"378,97556";"0,97264"
"2,00000";"1,67425";"381,30664";"0,97888"
"2,02000";"1,69081";"383,63953";"0,98565"
"2,04000";"1,70744";"385,93500";"0,99266"
"2,06000";"1,72412";"388,19312";"1,00008"
"2,08000";"1,74087";"390,47601";"1,00764"
"2,10000";"1,75762";"392,78030";"1,01684"
"2,12000";"1,77431";"395,05698";"1,02672"
"2,14000";"1,79112";"397,32977";"1,03672"
"2,16000";"1,80787";"399,58890";"1,04525"
"2,18000";"1,82450";"401,82126";"1,05553"
"2,20000";"1,84112";"404,00238";"1,06623"
"2,22000";"1,85775";"406,16791";"1,07594"
"2,24000";"1,87437";"408,30853";"1,08558"
"2,26000";"1,89094";"410,43723";"1,09312"
"2,28000";"1,90756";"412,57004";"1,10003"
"2,30000";"1,92419";"414,65326";"1,10658"
"2,32000";"1,94081";"416,74332";"1,11545"
"2,34000";"1,95737";"418,83115";"1,12365"
"2,36000";"1,97406";"420,87982";"1,13291"
"2,38000";"1,99081";"422,93774";"1,14284"
"2,40000";"2,00756";"425,03503";"1,15301"
"2,42000";"2,02425";"427,11331";"1,16351"
"2,44000";"2,04106";"429,14658";"1,17496"
"2,46000";"2,05781";"431,19568";"1,18500"
"2,48000";"2,07450";"433,22574";"1,19367"
"2,50000";"2,09112";"435,20779";"1,20296"
"2,52000";"2,10781";"437,15964";"1,21179"
"2,54000";"2,12444";"439,11273";"1,21978"
"2,56000";"2,14100";"441,04236";"1,22741"
"2,58000";"2,15762";"442,95157";"1,23570"
"2,60000";"2,17425";"444,83282";"1,24443"
"2,62000";"2,19081";"446,72278";"1,25276"
"2,64000";"2,20731";"448,58871";"1,26191"
"2,66000";"2,22400";"450,44446";"1,27012"
"2,68000";"2,24075";"452,31747";"1,27791"
"2,70000";"2,25756";"454,21841";"1,28540"
"2,72000";"2,27431";"456,12100";"1,29384"
"2,74000";"2,29119";"457,98026";"1,30391"
"2,76000";"2,30800";"459,85687";"1,31458"
"2,78000";"2,32456";"461,70816";"1,32303"
"2,80000";"2,34119";"463,49030";"1,32879"
"2,82000";"2,35787";"465,23502";"1,33330"
"2,84000";"2,37450";"467,02887";"1,33972"
"2,86000";"2,39100";"468,76834";"1,34671"
"2,88000";"2,40762";"470,50040";"1,35530"
"2,90000";"2,42425";"472,19839";"1,36644"
"2,92000";"2,44081";"473,91812";"1,37931"
"2,94000";"2,45737";"475,62112";"1,39221"
"2,96000";"2,47406";"477,32214";"1,40436"
"2,98000";"2,49087";"479,03854";"1,41546"
"3,00000";"2,50762";"480,76239";"1,42519"
"3,02000";"2,52431";"482,49200";"1,43245"
"3,04000";"2,54112";"484,18451";"1,43874"
"3,06000";"2,55787";"485,87466";"1,44389"
"3,08000";"2,57450";"487,53650";"1,44852"
"3,10000";"2,59112";"489,14844";"1,45623"
"3,12000";"2,60781";"490,74594";"1,46670"
"3,14000";"2,62444";"492,34772";"1,47642"
"3,16000";"2,64100";"493,94812";"1,48581"
"3,18000";"2,65762";"495,51801";"1,49633"
"3,20000";"2,67425";"497,09421";"1,50535"
"3,22000";"2,69087";"498,66556";"1,51267"
"3,24000";"2,70750";"500,21851";"1,52033"
"3,26000";"2,72412";"501,76700";"1,52837"
"3,28000";"2,74081";"503,29428";"1,53587"
"3,30000";"2,75750";"504,84174";"1,54267"
"3,32000";"2,77425";"506,37115";"1,55041"
"3,34000";"2,79106";"507,91660";"1,56062"
"3,36000";"2,80787";"509,48157";"1,57264"
"3,38000";"2,82450";"510,99289";"1,58347"
"3,40000";"2,84106";"512,47424";"1,59052"
"3,42000";"2,85775";"513,91986";"1,59716"
"3,44000";"2,87437";"515,36804";"1,60371"
"3,46000";"2,89094";"516,81781";"1,61100"
"3,48000";"2,90756";"518,25458";"1,62157"
"3,50000";"2,92425";"519,66821";"1,63356"
"3,52000";"2,94081";"521,09784";"1,64658"
"3,54000";"2,95737";"522,50818";"1,65985"
"3,56000";"2,97406";"523,89996";"1,67479"
"3,58000";"2,99081";"525,32086";"1,68737"
"3,60000";"3,00756";"526,76270";"1,69620"
"3,62000";"3,02425";"528,19391";"1,70456"
"3,64000";"3,04112";"529,61664";"1,71356"
"3,66000";"3,05787";"531,03735";"1,72317"
"3,68000";"3,07450";"532,41638";"1,73287"
"3,70000";"3,09112";"533,77509";"1,74135"
"3,72000";"3,10781";"535,08691";"1,74825"
"3,74000";"3,12444";"536,42920";"1,75652"
"3,76000";"3,14100";"537,75513";"1,76560"
"3,78000";"3,15762";"539,05780";"1,77531"
"3,80000";"3,17425";"540,35748";"1,78597"
"3,82000";"3,19081";"541,64508";"1,79596"
"3,84000";"3,20737";"542,91840";"1,80411"
"3,86000";"3,22400";"544,19434";"1,81286"
"3,88000";"3,24081";"545,48492";"1,82303"
"3,90000";"3,25756";"546,78613";"1,83426"
"3,92000";"3,27431";"548,10376";"1,84704"
"3,94000";"3,29119";"549,39404";"1,86081"
"3,96000";"3,30800";"550,69147";"1,87205"
"3,98000";"3,32462";"551,96094";"1,88098"
"4,00000";"3,34119";"553,22168";"1,88809"
"4,02000";"3,35787";"554,41992";"1,89581"
"4,04000";"3,37450";"555,61218";"1,90409"
"4,06000";"3,39106";"556,81268";"1,91083"
"4,08000";"3,40762";"557,99036";"1,91680"
"4,10000";"3,42431";"559,16681";"1,92517"
"4,12000";"3,44087";"560,34723";"1,93382"
"4,14000";"3,45744";"561,51892";"1,94342"
"4,16000";"3,47412";"562,66705";"1,95270"
"4,18000";"3,49081";"563,84436";"1,95995"
"4,20000";"3,50756";"565,02472";"1,96842"
"4,22000";"3,52425";"566,21442";"1,97800"
"4,24000";"3,54112";"567,40576";"1,98622"
"4,26000";"3,55787";"568,56537";"1,99370"
"4,28000";"3,57450";"569,72949";"2,00131"
"4,30000";"3,59112";"570,84851";"2,00882"
"4,32000";"3,60781";"571,94830";"2,01673"
"4,34000";"3,62444";"573,03998";"2,02784"
"4,36000";"3,64094";"574,13275";"2,03995"
"4,38000";"3,65756";"575,22906";"2,05138"
"4,40000";"3,67425";"576,30615";"2,06289"
"4,42000";"3,69087";"577,37610";"2,07484"
"4,44000";"3,70744";"578,47260";"2,08682"
"4,46000";"3,72412";"579,54260";"2,09530"
"4,48000";"3,74081";"580,62646";"2,10222"
"4,50000";"3,75750";"581,69037";"2,10939"
"4,52000";"3,77419";"582,76874";"2,11683"
"4,54000";"3,79100";"583,83246";"2,12427"
"4,56000";"3,80781";"584,92908";"2,13376"
"4,58000";"3,82444";"585,98975";"2,14288"
"4,60000";"3,84106";"587,02704";"2,15213"
"4,62000";"3,85781";"588,04834";"2,16144"
"4,64000";"3,87444";"589,03900";"2,17190"
"4,66000";"3,89100";"590,04913";"2,18566"
"4,68000";"3,90762";"591,02112";"2,20082"
"4,70000";"3,92419";"591,99908";"2,21361"
"4,72000";"3,94081";"592,96503";"2,22208"
"4,74000";"3,95744";"593,92236";"2,22924"
"4,76000";"3,97406";"594,90540";"2,23633"
"4,78000";"3,99081";"595,89630";"2,24310"
"4,80000";"4,00750";"596,89240";"2,25008"
"4,82000";"4,02425";"597,86121";"2,25787"
"4,84000";"4,04112";"598,85687";"2,26707"
"4,86000";"4,05794";"599,84918";"2,27907"
"4,88000";"4,07456";"600,82343";"2,29492"
"4,90000";"4,09119";"601,74701";"2,30850"
"4,92000";"4,10787";"602,63800";"2,31878"
"4,94000";"4,12450";"603,56714";"2,32740"
"4,96000";"4,14106";"604,47559";"2,33576"
"4,98000";"4,15762";"605,36871";"2,34442"
"5,00000";"4,17425";"606,25806";"2,35368"
"5,02000";"4,19081";"607,13873";"2,36377"
"5,04000";"4,20737";"608,02216";"2,37184"
"5,06000";"4,22406";"608,89343";"2,38010"
"5,08000";"4,24081";"609,78253";"2,38887"
"5,10000";"4,25756";"610,67517";"2,40000"
"5,12000";"4,27431";"611,55804";"2,41233"
"5,14000";"4,29119";"612,45502";"2,42512"
"5,16000";"4,30794";"613,36249";"2,43673"
"5,18000";"4,32456";"614,23779";"2,44741"
"5,20000";"4,34112";"615,05591";"2,45821"
"5,22000";"4,35781";"615,85968";"2,46948"
"5,24000";"4,37444";"616,70264";"2,47864"
"5,26000";"4,39100";"617,52161";"2,48557"
"5,28000";"4,40762";"618,32648";"2,49345"
"5,30000";"4,42425";"619,12024";"2,50271"
"5,32000";"4,44087";"619,92377";"2,51383"
"5,34000";"4,45737";"620,73041";"2,52546"
"5,36000";"4,47406";"621,52124";"2,53739"
"5,38000";"4,49081";"622,33057";"2,54707"
"5,40000";"4,50750";"623,14777";"2,55493"
"5,42000";"4,52425";"623,96759";"2,56237"
"5,44000";"4,54106";"624,76727";"2,56971"
"5,46000";"4,55781";"625,59955";"2,57715"
"5,48000";"4,57450";"626,39532";"2,58475"
"5,50000";"4,59106";"627,17676";"2,59427"
"5,52000";"4,60775";"627,92914";"2,60443"
"5,54000";"4,62437";"628,66888";"2,61536"
"5,56000";"4,64094";"629,40045";"2,62690"
"5,58000";"4,65756";"630,13239";"2,63653"
"5,60000";"4,67419";"630,84906";"2,64459"
"5,62000";"4,69081";"631,59583";"2,65498"
"5,64000";"4,70737";"632,32806";"2,66812"
"5,66000";"4,72400";"633,05035";"2,68052"
"5,68000";"4,74075";"633,77045";"2,69271"
"5,70000";"4,75756";"634,51276";"2,70490"
"5,72000";"4,77425";"635,26215";"2,71551"
"5,74000";"4,79106";"635,99512";"2,72420"
"5,76000";"4,80781";"636,74359";"2,73264"
"5,78000";"4,82450";"637,48138";"2,74266"
"5,80000";"4,84112";"638,19202";"2,75331"
"5,82000";"4,85781";"638,87964";"2,76537"
"5,84000";"4,87450";"639,56781";"2,77933"
"5,86000";"4,89106";"640,25293";"2,79252"
"5,88000";"4,90762";"640,92474";"2,80217"
"5,90000";"4,92431";"641,60162";"2,80887"
"5,92000";"4,94087";"642,26031";"2,81546"
"5,94000";"4,95744";"642,90399";"2,82431"
"5,96000";"4,97412";"643,54150";"2,83443"
"5,98000";"4,99094";"644,22595";"2,84458"
"6,00000";"5,00762";"644,90875";"2,85562"
"6,02000";"5,02437";"645,60132";"2,86705"
"6,04000";"5,04119";"646,26306";"2,87838"
"6,06000";"5,05794";"646,92932";"2,88980"
"6,08000";"5,07456";"647,60767";"2,89945"
"6,10000";"5,09112";"648,23083";"2,90824"
"6,12000";"5,10781";"648,84399";"2,91605"
"6,14000";"5,12444";"649,44574";"2,92454"
"6,16000";"5,14100";"650,05975";"2,93226"
"6,18000";"5,15762";"650,64929";"2,94043"
"6,20000";"5,17431";"651,25287";"2,94801"
"6,22000";"5,19087";"651,84369";"2,95525"
"6,24000";"5,20744";"652,41766";"2,96245"
"6,26000";"5,22412";"652,99359";"2,97065"
"6,28000";"5,24081";"653,60590";"2,98251"
"6,30000";"5,25756";"654,23499";"2,99576"
"6,32000";"5,27431";"654,85120";"3,00902"
"6,34000";"5,29112";"655,48444";"3,02227"
"6,36000";"5,30787";"656,11633";"3,03495"
"6,38000";"5,32450";"656,71521";"3,04669"
"6,40000";"5,34106";"657,27997";"3,05503"
"6,42000";"5,35769";"657,81787";"3,06094"
"6,44000";"5,37437";"658,37683";"3,06563"
"6,46000";"5,39094";"658,94196";"3,07184"
"6,48000";"5,40756";"659,47211";"3,07960"
"6,50000";"5,42425";"660,00293";"3,08890"
"6,52000";"5,44081";"660,56049";"3,09901"
"6,54000";"5,45744";"661,09705";"3,10993"
"6,56000";"5,47406";"661,63300";"3,12306"
"6,58000";"5,49081";"662,17303";"3,13803"
"6,60000";"5,50750";"662,73364";"3,15565"
"6,62000";"5,52425";"663,28906";"3,16880"
"6,64000";"5,54106";"663,84448";"3,17708"
"6,66000";"5,55787";"664,41016";"3,18321"
"6,68000";"5,57450";"664,94281";"3,18895"
"6,70000";"5,59106";"665,43713";"3,19541"
"6,72000";"5,60775";"665,93665";"3,20265"
"6,74000";"5,62437";"666,42664";"3,21043"
"6,76000";"5,64094";"666,95935";"3,21870"
"6,78000";"5,65756";"667,47064";"3,22949"
"6,80000";"5,67425";"667,95728";"3,24008"
"6,82000";"5,69087";"668,44189";"3,25087"
"6,84000";"5,70737";"668,94409";"3,26198"
"6,86000";"5,72406";"669,41150";"3,27313"
"6,88000";"5,74081";"669,87494";"3,28592"
"6,90000";"5,75750";"670,38684";"3,29754"
"6,92000";"5,77425";"670,88501";"3,30622"
"6,94000";"5,79112";"671,40027";"3,31445"
"6,96000";"5,80787";"671,92993";"3,32409"
"6,98000";"5,82456";"672,42963";"3,33416"
"7,00000";"5,84119";"672,88715";"3,34318"
"7,02000";"5,85787";"673,33893";"3,35068"
"7,04000";"5,87450";"673,78693";"3,35750"
"7,06000";"5,89106";"674,24280";"3,36466"
"7,08000";"5,90769";"674,69263";"3,37376"
"7,10000";"5,92431";"675,12921";"3,38292"
"7,12000";"5,94087";"675,55530";"3,39374"
"7,14000";"5,95744";"675,97009";"3,40660"
"7,16000";"5,97412";"676,39844";"3,41939"
"7,18000";"5,99087";"676,85052";"3,43007"
"7,20000";"6,00756";"677,30585";"3,43995"
"7,22000";"6,02431";"677,75952";"3,44757"
"7,24000";"6,04112";"678,20758";"3,45495"
"7,26000";"6,05787";"678,65802";"3,46402"
"7,28000";"6,07450";"679,10785";"3,47549"
"7,30000";"6,09112";"679,54083";"3,48850"
"7,32000";"6,10781";"679,93579";"3,50008"
"7,34000";"6,12444";"680,35083";"3,51015"
"7,36000";"6,14106";"680,73743";"3,51859"
"7,38000";"6,15762";"681,12494";"3,52703"
"7,40000";"6,17425";"681,55157";"3,53574"
"7,42000";"6,19087";"681,95386";"3,54549"
"7,44000";"6,20744";"682,35321";"3,55595"
"7,46000";"6,22406";"682,73773";"3,56650"
"7,48000";"6,24081";"683,13202";"3,57715"
"7,50000";"6,25750";"683,51306";"3,58931"
"7,52000";"6,27425";"683,91388";"3,60492"
"7,54000";"6,29106";"684,32690";"3,61969"
"7,56000";"6,30787";"684,73615";"3,63317"
"7,58000";"6,32450";"685,15442";"3,64517"
"7,60000";"6,34112";"685,54443";"3,65571"
"7,62000";"6,35775";"685,88995";"3,66654"
"7,64000";"6,37437";"686,25049";"3,67761"
"7,66000";"6,39094";"686,60364";"3,68948"
"7,68000";"6,40756";"686,96222";"3,69952"
"7,70000";"6,42419";"687,32538";"3,70939"
"7,72000";"6,44081";"687,69128";"3,71993"
"7,74000";"6,45737";"688,03259";"3,72975"
"7,76000";"6,47400";"688,37726";"3,73977"
"7,78000";"6,49081";"688,72742";"3,75027"
"7,80000";"6,50756";"689,13904";"3,76227"
"7,82000";"6,52431";"689,53613";"3,77433"
"7,84000";"6,54119";"689,90729";"3,78748"
"7,86000";"6,55794";"690,29950";"3,80124"
"7,88000";"6,57456";"690,64386";"3,81697"
"7,90000";"6,59119";"690,97565";"3,82943"
"7,92000";"6,60781";"691,30688";"3,83970"
"7,94000";"6,62444";"691,62250";"3,84907"
"7,96000";"6,64100";"691,91925";"3,85687"
"7,98000";"6,65756";"692,24377";"3,86313"
"8,00000";"6,67419";"692,54236";"3,87117"
"8,02000";"6,69081";"692,85541";"3,87977"
"8,04000";"6,70744";"693,18115";"3,89057"
"8,06000";"6,72412";"693,49518";"3,90208"
"8,08000";"6,74087";"693,84418";"3,91429"
"8,10000";"6,75762";"694,18201";"3,92801"
"8,12000";"6,77437";"694,51660";"3,94020"
"8,14000";"6,79119";"694,86066";"3,95013"
"8,16000";"6,80794";"695,19641";"3,95998"
"8,18000";"6,82456";"695,50427";"3,97138"
"8,20000";"6,84112";"695,80121";"3,98272"
"8,22000";"6,85781";"696,08398";"3,99348"
"8,24000";"6,87450";"696,35101";"4,00408"
"8,26000";"6,89106";"696,67517";"4,01389"
"8,28000";"6,90762";"696,96649";"4,02564"
"8,30000";"6,92425";"697,23853";"4,03675"
"8,32000";"6,94087";"697,51208";"4,04583"
"8,34000";"6,95737";"697,78583";"4,05425"
"8,36000";"6,97406";"698,04028";"4,06257"
"8,38000";"6,99081";"698,30774";"4,07303"
"8,40000";"7,00750";"698,63239";"4,08348"
"8,42000";"7,02425";"698,93530";"4,09507"
"8,44000";"7,04112";"699,24847";"4,10719"
"8,46000";"7,05794";"699,57562";"4,11842"
"8,48000";"7,07450";"699,88733";"4,13013"
"8,50000";"7,09112";"700,13177";"4,14191"
"8,52000";"7,10775";"700,36432";"4,15386"
"8,54000";"7,12444";"700,61401";"4,16610"
"8,56000";"7,14100";"700,87476";"4,17752"
"8,58000";"7,15762";"701,13226";"4,18716"
"8,60000";"7,17425";"701,36017";"4,19680"
"8,62000";"7,19081";"701,62738";"4,20563"
"8,64000";"7,20737";"701,86749";"4,21413"
"8,66000";"7,22400";"702,10406";"4,22438"
"8,68000";"7,24075";"702,35156";"4,23688"
"8,70000";"7,25750";"702,63507";"4,24891"
"8,72000";"7,27425";"702,91559";"4,26221"
"8,74000";"7,29112";"703,19757";"4,27625"
"8,76000";"7,30787";"703,47925";"4,28808"
"8,78000";"7,32450";"703,73798";"4,29837"
"8,80000";"7,34112";"703,96313";"4,30571"
"8,82000";"7,35775";"704,17816";"4,31299"
"8,84000";"7,37437";"704,41907";"4,32301"
"8,86000";"7,39100";"704,65668";"4,33514"
"8,88000";"7,40756";"704,87305";"4,34804"
"8,90000";"7,42425";"705,07697";"4,36028"
"8,92000";"7,44081";"705,29492";"4,37182"
"8,94000";"7,45737";"705,53021";"4,38367"
"8,96000";"7,47406";"705,75903";"4,39709"
"8,98000";"7,49081";"706,00079";"4,40931"
"9,00000";"7,50750";"706,24811";"4,42080"
"9,02000";"7,52425";"706,46167";"4,43065"
"9,04000";"7,54112";"706,71765";"4,43713"
"9,06000";"7,55794";"706,97015";"4,44457"
"9,08000";"7,57456";"707,20593";"4,45133"
"9,10000";"7,59119";"707,42053";"4,45951"
"9,12000";"7,60781";"707,62189";"4,47275"
"9,14000";"7,62444";"707,85864";"4,49058"
"9,16000";"7,64100";"708,04828";"4,50613"
"9,18000";"7,65762";"708,22949";"4,51718"
"9,20000";"7,67425";"708,42200";"4,52729"
"9,22000";"7,69087";"708,61853";"4,53753"
"9,24000";"7,70744";"708,79730";"4,54948"
"9,26000";"7,72412";"708,99451";"4,56451"
"9,28000";"7,74087";"709,21063";"4,57811"
"9,30000";"7,75762";"709,43164";"4,58953"
"9,32000";"7,77437";"709,63940";"4,59940"
"9,34000";"7,79119";"709,83313";"4,60879"
"9,36000";"7,80794";"710,04944";"4,61959"
"9,38000";"7,82456";"710,26935";"4,63117"
"9,40000";"7,84112";"710,44824";"4,64398"
"9,42000";"7,85781";"710,60303";"4,65871"
"9,44000";"7,87444";"710,80438";"4,67341"
"9,46000";"7,89100";"710,98407";"4,68618"
"9,48000";"7,90762";"711,14655";"4,69880"
"9,50000";"7,92425";"711,30804";"4,71073"
"9,52000";"7,94081";"711,46906";"4,72232"
"9,54000";"7,95737";"711,63898";"4,73280"
"9,56000";"7,97406";"711,77155";"4,74223"
"9,58000";"7,99075";"711,93921";"4,75011"
"9,60000";"8,00750";"712,13641";"4,75775"
"9,62000";"8,02425";"712,35767";"4,76766"
"9,64000";"8,04112";"712,53381";"4,77813"
"9,66000";"8,05787";"712,71936";"4,78656"
"9,68000";"8,07450";"712,89795";"4,79240"
"9,70000";"8,09112";"713,04285";"4,79938"
"9,72000";"8,10781";"713,19940";"4,80827"
"9,74000";"8,12444";"713,35950";"4,82176"
"9,76000";"8,14100";"713,50537";"4,83812"
"9,78000";"8,15762";"713,65100";"4,85265"
"9,80000";"8,17425";"713,80780";"4,86551"
"9,82000";"8,19087";"713,95471";"4,87602"
"9,84000";"8,20737";"714,11609";"4,88580"
"9,86000";"8,22406";"714,26282";"4,89563"
"9,88000";"8,24081";"714,39380";"4,90647"
"9,90000";"8,25750";"714,56720";"4,91861"
"9,92000";"8,27425";"714,73846";"4,93253"
"9,94000";"8,29106";"714,91760";"4,94870"
"9,96000";"8,30787";"715,07806";"4,96568"
"9,98000";"8,32456";"715,26764";"4,97963"
"10,00000";"8,34112";"715,39478";"4,99072"
"10,02000";"8,35781";"715,53119";"5,00039"
"10,04000";"8,37444";"715,63959";"5,01274"
"10,06000";"8,39100";"715,75940";"5,02758"
"10,08000";"8,40756";"715,89545";"5,04157"
"10,10000";"8,42425";"716,02631";"5,05226"
"10,12000";"8,44081";"716,16693";"5,06069"
"10,14000";"8,45744";"716,26416";"5,06765"
"10,16000";"8,47412";"716,40216";"5,07622"
"10,18000";"8,49087";"716,54297";"5,08748"
"10,20000";"8,50756";"716,70105";"5,09906"
"10,22000";"8,52431";"716,85913";"5,10894"
"10,24000";"8,54106";"717,00165";"5,11990"
"10,26000";"8,55787";"717,16852";"5,13234"
"10,28000";"8,57444";"717,31567";"5,14560"
"10,30000";"8,59106";"717,42987";"5,15772"
"10,32000";"8,60781";"717,52039";"5,16869"
"10,34000";"8,62444";"717,64447";"5,17877"
"10,36000";"8,64106";"717,74371";"5,18900"
"10,38000";"8,65769";"717,86194";"5,20027"
"10,40000";"8,67431";"717,98083";"5,21358"
"10,42000";"8,69087";"718,08881";"5,23075"
"10,44000";"8,70744";"718,17999";"5,24937"
"10,46000";"8,72412";"718,26654";"5,26352"
"10,48000";"8,74087";"718,36584";"5,27343"
"10,50000";"8,75756";"718,49292";"5,28223"
"10,52000";"8,77431";"718,62482";"5,29200"
"10,54000";"8,79106";"718,75140";"5,30303"
"10,56000";"8,80781";"718,90131";"5,31329"
"10,58000";"8,82450";"719,03662";"5,32322"
"10,60000";"8,84112";"719,13910";"5,33273"
"10,62000";"8,85781";"719,22870";"5,34159"
"10,64000";"8,87444";"719,34467";"5,35540"
"10,66000";"8,89106";"719,44586";"5,36955"
"10,68000";"8,90769";"719,51862";"5,38281"
"10,70000";"8,92431";"719,59009";"5,39596"
"10,72000";"8,94094";"719,68549";"5,41092"
"10,74000";"8,95744";"719,78113";"5,42513"
"10,76000";"8,97406";"719,87048";"5,43808"
"10,78000";"8,99081";"719,97034";"5,45004"
"10,80000";"9,00750";"720,08521";"5,46167"
"10,82000";"9,02425";"720,21143";"5,47137"
"10,84000";"9,04106";"720,31726";"5,48060"
"10,86000";"9,05787";"720,45282";"5,48948"
"10,88000";"9,07450";"720,56256";"5,50006"
"10,90000";"9,09112";"720,63348";"5,51208"
"10,92000";"9,10775";"720,71814";"5,52444"
"10,94000";"9,12444";"720,78961";"5,53702"
"10,96000";"9,14100";"720,87811";"5,54879"
"10,98000";"9,15756";"720,94702";"5,56018"
"11,00000";"9,17419";"721,01941";"5,56934"
"11,02000";"9,19081";"721,08423";"5,57838"
"11,04000";"9,20737";"721,14581";"5,58549"
"11,06000";"9,22400";"721,20807";"5,59227"
"11,08000";"9,24075";"721,29211";"5,60201"
"11,10000";"9,25750";"721,41534";"5,61358"
"11,12000";"9,27425";"721,50977";"5,62523"
"11,14000";"9,29106";"721,61792";"5,63862"
"11,16000";"9,30794";"721,72412";"5,65581"
"11,18000";"9,32456";"721,84741";"5,67403"
"11,20000";"9,34119";"721,89838";"5,69089"
"11,22000";"9,35781";"721,93542";"5,70604"
"11,24000";"9,37444";"721,99469";"5,71960"
"11,26000";"9,39100";"722,04108";"5,73206"
"11,28000";"9,40756";"722,09558";"5,74117"
"11,30000";"9,42419";"722,16235";"5,74978"
"11,32000";"9,44087";"722,23584";"5,76000"
"11,34000";"9,45744";"722,29053";"5,77184"
"11,36000";"9,47406";"722,34705";"5,78425"
"11,38000";"9,49087";"722,42224";"5,79736"
"11,40000";"9,50756";"722,52057";"5,80990"
"11,42000";"9,52437";"722,61212";"5,82096"
"11,44000";"9,54119";"722,71478";"5,83005"
"11,46000";"9,55787";"722,79834";"5,83858"
"11,48000";"9,57456";"722,86420";"5,84821"
"11,50000";"9,59119";"722,90179";"5,85975"
"11,52000";"9,60781";"722,95703";"5,87275"
"11,54000";"9,62450";"722,99316";"5,88659"
"11,56000";"9,64106";"723,04272";"5,90089"
"11,58000";"9,65769";"723,08710";"5,91410"
"11,60000";"9,67431";"723,14142";"5,92643"
"11,62000";"9,69094";"723,18756";"5,93768"
"11,64000";"9,70750";"723,21350";"5,95027"
"11,66000";"9,72412";"723,24066";"5,96117"
"11,68000";"9,74087";"723,30768";"5,97109"
"11,70000";"9,75762";"723,37769";"5,98116"
"11,72000";"9,77431";"723,42798";"5,98946"
"11,74000";"9,79112";"723,50079";"5,99932"
"11,76000";"9,80787";"723,59259";"6,01442"
"11,78000";"9,82450";"723,65570";"6,02804"
"11,80000";"9,84112";"723,68311";"6,04133"
"11,82000";"9,85775";"723,71466";"6,05298"
"11,84000";"9,87444";"723,74561";"6,06483"
"11,86000";"9,89100";"723,77863";"6,07765"
"11,88000";"9,90756";"723,81177";"6,08932"
"11,90000";"9,92425";"723,84210";"6,09963"
"11,92000";"9,94087";"723,88434";"6,11294"
"11,94000";"9,95744";"723,92517";"6,12671"
"11,96000";"9,97406";"723,94940";"6,13983"
"11,98000";"9,99081";"723,99792";"6,15383"
"12,00000";"10,00750";"724,03632";"6,17045"
"12,02000";"10,02425";"724,09137";"6,18577"
"12,04000";"10,04106";"724,15826";"6,20063"
"12,06000";"10,05787";"724,25732";"6,21448"
"12,08000";"10,07450";"724,31433";"6,22546"
"12,10000";"10,09106";"724,33545";"6,23268"
"12,12000";"10,10775";"724,33844";"6,23865"
"12,14000";"10,12437";"724,36243";"6,24824"
"12,16000";"10,14093";"724,39288";"6,26018"
"12,18000";"10,15756";"724,41241";"6,27370"
"12,20000";"10,17419";"724,43823";"6,28579"
"12,22000";"10,19081";"724,46948";"6,29814"
"12,24000";"10,20737";"724,48181";"6,31072"
"12,26000";"10,22406";"724,48999";"6,32185"
"12,28000";"10,24087";"724,51599";"6,33432"
"12,30000";"10,25756";"724,56122";"6,34805"
"12,32000";"10,27431";"724,61670";"6,36108"
"12,34000";"10,29112";"724,67169";"6,37335"
"12,36000";"10,30793";"724,72955";"6,38579"
"12,38000";"10,32456";"724,76477";"6,39660"
"12,40000";"10,34119";"724,76965";"6,40559"
"12,42000";"10,35781";"724,77563";"6,41456"
"12,44000";"10,37444";"724,77325";"6,42649"
"12,46000";"10,39094";"724,78107";"6,43959"
"12,48000";"10,40756";"724,80194";"6,45051"
"12,50000";"10,42425";"724,81769";"6,46324"
"12,52000";"10,44087";"724,84357";"6,47692"
"12,54000";"10,45744";"724,87476";"6,49228"
"12,56000";"10,47412";"724,89270";"6,50631"
"12,58000";"10,49087";"724,91803";"6,51791"
"12,60000";"10,50756";"724,93298";"6,52652"
"12,62000";"10,52431";"724,96100";"6,53382"
"12,64000";"10,54112";"724,98773";"6,54140"
"12,66000";"10,55787";"725,03912";"6,54813"
"12,68000";"10,57450";"725,06537";"6,55750"
"12,70000";"10,59112";"725,06958";"6,57293"
"12,72000";"10,60781";"725,05353";"6,59378"
"12,74000";"10,62444";"725,03497";"6,61419"
"12,76000";"10,64100";"725,03259";"6,62974"
"12,78000";"10,65762";"725,05469";"6,64334"
"12,80000";"10,67431";"725,06018";"6,65660"
"12,82000";"10,69087";"725,04095";"6,66861"
"12,84000";"10,70744";"725,04187";"6,68196"
"12,86000";"10,72412";"725,04486";"6,69566"
"12,88000";"10,74081";"725,05017";"6,71033"
"12,90000";"10,75756";"725,07660";"6,72463"
"12,92000";"10,77425";"725,11035";"6,73584"
"12,94000";"10,79106";"725,12994";"6,74730"
"12,96000";"10,80781";"725,16394";"6,75898"
"12,98000";"10,82444";"725,17401";"6,77193"
"13,00000";"10,84106";"725,17139";"6,78494"
"13,02000";"10,85775";"725,17023";"6,79854"
"13,04000";"10,87437";"725,16113";"6,81017"
"13,06000";"10,89094";"725,16779";"6,81972"
"13,08000";"10,90756";"725,15326";"6,83105"
"13,10000";"10,92419";"725,13501";"6,84189"
"13,12000";"10,94081";"725,12799";"6,85283"
"13,14000";"10,95737";"725,11517";"6,86033"
"13,16000";"10,97400";"725,09003";"6,86747"
"13,18000";"10,99075";"725,09082";"6,88093"
"13,20000";"11,00750";"725,11243";"6,89885"
"13,22000";"11,02425";"725,15369";"6,91971"
"13,24000";"11,04106";"725,18134";"6,93816"
"13,26000";"11,05787";"725,20862";"6,95330"
"13,28000";"11,07450";"725,22992";"6,96598"
"13,30000";"11,09119";"725,21863";"6,97580"
"13,32000";"11,10787";"725,18842";"6,98370"
"13,34000";"11,12443";"725,17340";"6,98973"
"13,36000";"11,14100";"725,14728";"6,99635"
"13,38000";"11,15756";"725,11346";"7,00612"
"13,40000";"11,17425";"725,07538";"7,01963"
"13,42000";"11,19081";"725,06891";"7,03670"
"13,44000";"11,20737";"725,06323";"7,05614"
"13,46000";"11,22412";"725,05707";"7,07094"
"13,48000";"11,24094";"725,06830";"7,08123"
"13,50000";"11,25762";"725,09723";"7,09214"
"13,52000";"11,27437";"725,10077";"7,10508"
"13,54000";"11,29125";"725,10541";"7,12032"
"13,56000";"11,30800";"725,12610";"7,13582"
"13,58000";"11,32462";"725,12756";"7,15170"
"13,60000";"11,34119";"725,10144";"7,16639"
"13,62000";"11,35781";"725,07074";"7,17869"
"13,64000";"11,37450";"725,04767";"7,18949"
"13,66000";"11,39100";"725,02271";"7,20019"
"13,68000";"11,40762";"724,97736";"7,21072"
"13,70000";"11,42431";"724,94739";"7,22217"
"13,72000";"11,44087";"724,90460";"7,23270"
"13,74000";"11,45744";"724,88739";"7,24372"
"13,76000";"11,47406";"724,87152";"7,25582"
"13,78000";"11,49087";"724,85486";"7,26870"
"13,80000";"11,50762";"724,85657";"7,28169"
"13,82000";"11,52431";"724,84784";"7,29552"
"13,84000";"11,54119";"724,84955";"7,31347"
"13,86000";"11,55787";"724,85046";"7,33244"
"13,88000";"11,57444";"724,84369";"7,34688"
"13,90000";"11,59106";"724,80798";"7,35668"
"13,92000";"11,60775";"724,76581";"7,36582"
"13,94000";"11,62437";"724,73267";"7,37477"
"13,96000";"11,64100";"724,70776";"7,38486"
"13,98000";"11,65762";"724,68097";"7,39476"
"14,00000";"11,67425";"724,63214";"7,40571"
"14,02000";"11,69081";"724,58905";"7,41683"
"14,04000";"11,70737";"724,55975";"7,42819"
"14,06000";"11,72400";"724,53156";"7,43935"
"14,08000";"11,74075";"724,50531";"7,45212"
"14,10000";"11,75743";"724,48035";"7,46767"
"14,12000";"11,77412";"724,45325";"7,48365"
"14,14000";"11,79106";"724,46674";"7,50124"
"14,16000";"11,80787";"724,46301";"7,51658"
"14,18000";"11,82450";"724,47357";"7,52787"
"14,20000";"11,84112";"724,46295";"7,53656"
"14,22000";"11,85775";"724,39954";"7,54703"
"14,24000";"11,87437";"724,34625";"7,56169"
"14,26000";"11,89100";"724,30548";"7,57758"
"14,28000";"11,90762";"724,27216";"7,59238"
"14,30000";"11,92425";"724,22168";"7,60511"
"14,32000";"11,94081";"724,19061";"7,61628"
"14,34000";"11,95731";"724,14655";"7,62812"
"14,36000";"11,97400";"724,10968";"7,64300"
"14,38000";"11,99075";"724,07336";"7,66109"
"14,40000";"12,00750";"724,05286";"7,67973"
"14,42000";"12,02425";"724,04443";"7,69531"
"14,44000";"12,04119";"724,05090";"7,70488"
"14,46000";"12,05794";"724,05292";"7,71164"
"14,48000";"12,07462";"724,02856";"7,71824"
"14,50000";"12,09118";"723,98254";"7,72762"
"14,52000";"12,10787";"723,91241";"7,74037"
"14,54000";"12,12450";"723,86493";"7,75361"
"14,56000";"12,14100";"723,80835";"7,76538"
"14,58000";"12,15762";"723,74518";"7,77633"
"14,60000";"12,17431";"723,70612";"7,78763"
"14,62000";"12,19087";"723,65045";"7,80172"
"14,64000";"12,20744";"723,61462";"7,82083"
"14,66000";"12,22412";"723,56427";"7,83959"
"14,68000";"12,24087";"723,53046";"7,85366"
"14,70000";"12,25762";"723,51965";"7,86347"
"14,72000";"12,27431";"723,50500";"7,87269"
"14,74000";"12,29112";"723,48694";"7,88235"
"14,76000";"12,30794";"723,47754";"7,89411"
"14,78000";"12,32456";"723,47296";"7,90800"
"14,80000";"12,34119";"723,40631";"7,92430"
"14,82000";"12,35781";"723,32593";"7,94113"
"14,84000";"12,37444";"723,27057";"7,95671"
"14,86000";"12,39100";"723,21863";"7,96981"
"14,88000";"12,40756";"723,16022";"7,98026"
"14,90000";"12,42425";"723,07520";"7,99245"
"14,92000";"12,44087";"723,04858";"8,00512"
"14,94000";"12,45744";"722,99866";"8,01831"
"14,96000";"12,47412";"722,92914";"8,03329"
"14,98000";"12,49087";"722,87189";"8,04888"
"15,00000";"12,50756";"722,85675";"8,06180"
"15,02000";"12,52431";"722,83997";"8,07535"
"15,04000";"12,54112";"722,81128";"8,09094"
"15,06000";"12,55781";"722,78351";"8,10806"
"15,08000";"12,57444";"722,73584";"8,12156"
"15,10000";"12,59106";"722,65533";"8,13343"
"15,12000";"12,60775";"722,59955";"8,14403"
"15,14000";"12,62437";"722,54584";"8,15497"
"15,16000";"12,64093";"722,49561";"8,16553"
"15,18000";"12,65756";"722,42041";"8,17644"
"15,20000";"12,67419";"722,35852";"8,19035"
"15,22000";"12,69075";"722,29175";"8,20832"
"15,24000";"12,70731";"722,23706";"8,22446"
"15,26000";"12,72400";"722,15668";"8,23573"
"15,28000";"12,74075";"722,11041";"8,24702"
"15,30000";"12,75750";"722,06775";"8,26132"
"15,32000";"12,77425";"722,04871";"8,27594"
"15,34000";"12,79106";"722,03876";"8,29027"
"15,36000";"12,80794";"722,03107";"8,30187"
"15,38000";"12,82456";"722,00012";"8,31487"
"15,40000";"12,84119";"721,92432";"8,32854"
"15,42000";"12,85781";"721,87732";"8,34364"
"15,44000";"12,87444";"721,78992";"8,35777"
"15,46000";"12,89106";"721,73444";"8,37080"
"15,48000";"12,90762";"721,66522";"8,38193"
"15,50000";"12,92425";"721,60175";"8,39153"
"15,52000";"12,94087";"721,53247";"8,40069"
"15,54000";"12,95743";"721,44727";"8,41017"
"15,56000";"12,97412";"721,38025";"8,42092"
"15,58000";"12,99087";"721,32007";"8,43605"
"15,60000";"13,00756";"721,28156";"8,45131"
"15,62000";"13,02431";"721,24445";"8,46494"
"15,64000";"13,04112";"721,22241";"8,47935"
"15,66000";"13,05793";"721,19965";"8,49383"
"15,68000";"13,07456";"721,15784";"8,50874"
"15,70000";"13,09119";"721,08014";"8,52007"
"15,72000";"13,10787";"721,02136";"8,53195"
"15,74000";"13,12450";"720,92859";"8,54752"
"15,76000";"13,14106";"720,84546";"8,56819"
"15,78000";"13,15762";"720,74286";"8,59219"
"15,80000";"13,17425";"720,67822";"8,60997"
"15,82000";"13,19081";"720,60876";"8,62147"
"15,84000";"13,20743";"720,55939";"8,62984"
"15,86000";"13,22412";"720,46985";"8,63784"
"15,88000";"13,24094";"720,43268";"8,64581"
"15,90000";"13,25762";"720,40314";"8,65775"
"15,92000";"13,27431";"720,34949";"8,66984"
"15,94000";"13,29112";"720,31177";"8,68076"
"15,96000";"13,30781";"720,26086";"8,69048"
"15,98000";"13,32444";"720,18964";"8,70101"
"16,00000";"13,34106";"720,09729";"8,71227"
"16,02000";"13,35769";"720,02448";"8,72792"
"16,04000";"13,37437";"719,95435";"8,74724"
"16,06000";"13,39100";"719,89508";"8,76793"
"16,08000";"13,40762";"719,82831";"8,78717"
"16,10000";"13,42431";"719,74622";"8,80301"
"16,12000";"13,44087";"719,68048";"8,81480"
"16,14000";"13,45744";"719,58032";"8,82499"
"16,16000";"13,47406";"719,50623";"8,83713"
"16,18000";"13,49081";"719,44403";"8,85199"
"16,20000";"13,50750";"719,40131";"8,86861"
"16,22000";"13,52425";"719,35193";"8,88373"
"16,24000";"13,54106";"719,30145";"8,89619"
"16,26000";"13,55781";"719,26556";"8,90785"
"16,28000";"13,57444";"719,21521";"8,92096"
"16,30000";"13,59106";"719,14105";"8,93586"
"16,32000";"13,60775";"719,06378";"8,95266"
"16,34000";"13,62444";"718,99817";"8,97008"
"16,36000";"13,64100";"718,90698";"8,98849"
"16,38000";"13,65762";"718,82727";"9,00590"
"16,40000";"13,67425";"718,74274";"9,02340"
"16,42000";"13,69081";"718,65778";"9,04059"
"16,44000";"13,70737";"718,55963";"9,05565"
"16,46000";"13,72406";"718,47455";"9,06844"
"16,48000";"13,74081";"718,41681";"9,07930"
"16,50000";"13,75750";"718,36591";"9,08956"
"16,52000";"13,77431";"718,32324";"9,10130"
"16,54000";"13,79118";"718,27875";"9,11803"
"16,56000";"13,80794";"718,22412";"9,13596"
"16,58000";"13,82462";"718,18719";"9,15326"
"16,60000";"13,84119";"718,09729";"9,16989"
"16,62000";"13,85787";"718,00189";"9,18613"
"16,64000";"13,87443";"717,90271";"9,20065"
"16,66000";"13,89106";"717,83130";"9,21311"
"16,68000";"13,90762";"717,73706";"9,22671"
"16,70000";"13,92431";"717,64655";"9,24405"
"16,72000";"13,94087";"717,55444";"9,26288"
"16,74000";"13,95744";"717,45386";"9,27884"
"16,76000";"13,97406";"717,37091";"9,29224"
"16,78000";"13,99081";"717,29065";"9,30637"
"16,80000";"14,00750";"717,23438";"9,32221"
"16,82000";"14,02425";"717,16907";"9,33960"
"16,84000";"14,04112";"717,11414";"9,35575"
"16,86000";"14,05794";"717,06982";"9,36986"
"16,88000";"14,07456";"717,01544";"9,38343"
"16,90000";"14,09119";"716,93927";"9,39499"
"16,92000";"14,10781";"716,83099";"9,40794"
"16,94000";"14,12444";"716,71472";"9,42297"
"16,96000";"14,14100";"716,61676";"9,43746"
"16,98000";"14,15756";"716,51648";"9,45111"
"17,00000";"14,17425";"716,41498";"9,46496"
"17,02000";"14,19081";"716,34241";"9,47799"
"17,04000";"14,20737";"716,25812";"9,49141"
"17,06000";"14,22406";"716,17194";"9,50551"
"17,08000";"14,24081";"716,09253";"9,52267"
"17,10000";"14,25750";"716,02313";"9,53839"
"17,12000";"14,27425";"715,95428";"9,54862"
"17,14000";"14,29106";"715,88611";"9,55585"
"17,16000";"14,30781";"715,82581";"9,56550"
"17,18000";"14,32444";"715,74158";"9,58012"
"17,20000";"14,34106";"715,66479";"9,59625"
"17,22000";"14,35775";"715,57361";"9,61172"
"17,24000";"14,37444";"715,47919";"9,62693"
"17,26000";"14,39100";"715,36469";"9,64100"
"17,28000";"14,40762";"715,26642";"9,65427"
"17,30000";"14,42425";"715,16022";"9,66917"
"17,32000";"14,44081";"715,06024";"9,68460"
"17,34000";"14,45737";"714,96613";"9,69815"
"17,36000";"14,47406";"714,87958";"9,71123"
"17,38000";"14,49081";"714,77893";"9,72751"
"17,40000";"14,50756";"714,70874";"9,74297"
"17,42000";"14,52431";"714,65277";"9,75738"
"17,44000";"14,54112";"714,59943";"9,77079"
"17,46000";"14,55787";"714,53864";"9,78234"
"17,48000";"14,57456";"714,44476";"9,79512"
"17,50000";"14,59112";"714,35767";"9,80989"
"17,52000";"14,60781";"714,24634";"9,82617"
"17,54000";"14,62444";"714,16772";"9,84596"
"17,56000";"14,64100";"714,06396";"9,86838"
"17,58000";"14,65756";"713,94043";"9,88599"
"17,60000";"14,67425";"713,84552";"9,89748"
"17,62000";"14,69087";"713,76227";"9,90870"
"17,64000";"14,70744";"713,64441";"9,92036"
"17,66000";"14,72412";"713,53943";"9,93401"
"17,68000";"14,74087";"713,45502";"9,94849"
"17,70000";"14,75756";"713,40198";"9,96151"
"17,72000";"14,77425";"713,32434";"9,97428"
"17,74000";"14,79119";"713,25818";"9,98742"
"17,76000";"14,80794";"713,19550";"10,00166"
"17,78000";"14,82456";"713,11707";"10,01504"
"17,80000";"14,84118";"713,02319";"10,02876"
"17,82000";"14,85787";"712,89679";"10,04256"
"17,84000";"14,87450";"712,79205";"10,05933"
"17,86000";"14,89106";"712,68005";"10,07888"
"17,88000";"14,90762";"712,55878";"10,09546"
"17,90000";"14,92425";"712,44049";"10,10573"
"17,92000";"14,94081";"712,31091";"10,11403"
"17,94000";"14,95744";"712,20996";"10,12475"
"17,96000";"14,97412";"712,09857";"10,14038"
"17,98000";"14,99087";"712,00562";"10,16178"
"18,00000";"15,00762";"711,93250";"10,18074"
"18,02000";"15,02431";"711,86774";"10,19513"
"18,04000";"15,04112";"711,77698";"10,20597"
"18,06000";"15,05787";"711,67999";"10,21669"
"18,08000";"15,07450";"711,59216";"10,23187"
"18,10000";"15,09112";"711,48303";"10,24949"
"18,12000";"15,10775";"711,35754";"10,26762"
"18,14000";"15,12437";"711,24365";"10,28500"
"18,16000";"15,14093";"711,13513";"10,29986"
"18,18000";"15,15756";"711,01038";"10,31097"
"18,20000";"15,17425";"710,90936";"10,32105"
"18,21200";"15,18425";"710,84991";"10,32758"
"18,22400";"15,19681";"710,79895";"10,33563"
"18,24400";"15,25968";"712,21368";"10,35403"
"18,26400";"15,38125";"719,64679";"10,38733"
"18,28400";"15,55544";"734,49255";"10,45475"
"18,30400";"15,75425";"752,39105";"10,56207"
"18,32400";"15,96356";"768,56171";"10,70109"
"18,34400";"16,17850";"780,39038";"10,85861"
"18,36400";"16,38287";"787,66321";"11,02999"
"18,38400";"16,56731";"790,47369";"11,20599"
"18,40400";"16,73800";"790,04669";"11,37532"
"18,42400";"16,90400";"787,96851";"11,53029"
"18,44400";"17,07068";"785,58063";"11,68440"
"18,46400";"17,23919";"783,31818";"11,83900"
"18,48400";"17,40862";"781,15106";"11,99213"
"18,50400";"17,57793";"778,72754";"12,15248"
"18,52400";"17,74656";"775,67236";"12,31902"
"18,54400";"17,91456";"772,24976";"12,48612"
"18,56400";"18,08187";"768,35828";"12,65167"
"18,58400";"18,24893";"763,75098";"12,81384"
"18,60400";"18,41594";"758,68005";"12,98049"
"18,62400";"18,58294";"753,50201";"13,15705"
"18,64400";"18,75000";"747,57135";"13,33360"
"18,66400";"18,91700";"741,25183";"13,50823"
"18,68400";"19,08375";"734,74469";"13,68601"
"18,70400";"19,25043";"727,61816";"13,86279"
"18,72400";"19,41725";"720,14490";"14,04274"
"18,74400";"19,58406";"712,54907";"14,22691"
"18,76400";"19,75087";"704,37952";"14,41355"
"18,78400";"19,91756";"695,72443";"14,59267"
"18,80400";"20,08418";"686,78381";"14,77445"
"18,82400";"20,25081";"677,00128";"14,95366"
"18,84400";"20,41762";"666,57178";"15,13638"
"18,86400";"20,58431";"655,64288";"15,32695"
"18,88400";"20,75100";"643,83844";"15,51667"
"18,90400";"20,91756";"631,42334";"15,70809"
"18,92400";"21,08425";"619,10516";"15,89896"
"18,94400";"21,25093";"606,88928";"16,08720"
"18,96400";"21,41768";"595,19617";"16,27874"
"18,98400";"21,58437";"584,61444";"16,47407"
"19,00400";"21,75093";"574,85205";"16,66421"
"19,02400";"21,91750";"565,95056";"16,84979"
"19,04400";"22,08418";"558,14941";"17,04337"
"19,06400";"22,25093";"551,17047";"17,23156"
"19,08400";"22,41768";"545,19208";"17,41402"
"19,10400";"22,58443";"540,31519";"17,60057"
"19,12400";"22,75100";"536,05200";"17,79004"
"19,14400";"22,91768";"532,29211";"17,96892"
"19,16400";"23,08431";"529,22815";"18,14898"
"19,18400";"23,25106";"526,45398";"18,32649"
"19,20400";"23,41775";"523,83350";"18,49638"
"19,22400";"23,58437";"521,60284";"18,66827"
"19,24400";"23,75100";"519,42542";"18,84178"
"19,26400";"23,91768";"517,40869";"19,01262"
"19,28400";"24,08443";"515,83051";"19,18712"
"19,30400";"24,25112";"514,33051";"19,36269"
"19,32400";"24,41775";"512,87177";"19,54258"
"19,34400";"24,58431";"511,87073";"19,71550"
"19,36400";"24,75093";"510,62723";"19,88839"
"19,38400";"24,91768";"509,49448";"20,05692"
"19,40400";"25,08443";"508,43124";"20,23233"
"19,42400";"25,25106";"507,07144";"20,41039"
"19,44400";"25,41768";"505,54431";"20,58511"
"19,46400";"25,58425";"504,17801";"20,75338"
"19,48400";"25,75093";"502,44379";"20,92061"
"19,50400";"25,91768";"500,29465";"21,09358"
"19,52400";"26,08437";"496,04874";"21,26902"
"19,54400";"26,25093";"488,48224";"21,45547"
"19,56400";"26,41756";"481,00464";"21,63966"
"19,58400";"26,58425";"474,84647";"21,81958"
"19,60400";"26,75093";"469,25644";"22,00045"
"19,62400";"26,91768";"463,56488";"22,17987"
"19,64400";"27,08425";"457,34579";"22,35717"
"19,66400";"27,25081";"449,65970";"22,54291"
"19,68400";"27,41756";"441,29184";"22,73438"
"19,70400";"27,58437";"433,15952";"22,92945"
"19,72400";"27,75112";"424,62140";"23,12823"
"19,74400";"27,91774";"414,48038";"23,32317"
"19,76400";"28,08431";"402,86963";"23,52330"
"19,78400";"28,25093";"381,98331";"23,73096"
"19,79800";"28,36769";"259,31808";"23,95987"